Workbook

Sheet Questions
D1: Expert 1 | G1: Expert 2 | J1: Expert 3
A2: Index | B2: Modeling Stage | C2: Risk Event | D2: Occurence | E2: Detection | F2: Severity | G2: Occurence | H2: Detection | I2: Severity | J2: Occurence | K2: Detection | L2: Severity
A3: 1 | B3: Business Understanding | C3: The objectives of the modeling process are not clearly defined from the outset. | D3: 8 | E3: 7 | F3: 8 | G3: 7 | H3: 7 | I3: 8 | J3: 8 | K3: 4 | L3: 8
A4: 2 | B4: Business Understanding | C4: Regulatory requirements are misinterpreted by the involved teams. | D4: 10 | E4: 3 | F4: 7 | G4: 10 | H4: 4 | I4: 9 | J4: 8 | K4: 5 | L4: 6
A5: 3 | B5: Business Understanding | C5: There are communication failures among the risk, accounting, IT, and business areas. | D5: 10 | E5: 5 | F5: 8 | G5: 8 | H5: 6 | I5: 5 | J5: 8 | K5: 6 | L5: 4
A6: 4 | B6: Business Understanding | C6: Responsibilities in the modeling process are not clearly distributed. | D6: 10 | E6: 8 | F6: 10 | G6: 8 | H6: 5 | I6: 8 | J6: 7 | K6: 5 | L6: 9
A7: 5 | B7: Business Understanding | C7: There is no formal process to review and update the modeling scope. | D7: 10 | E7: 10 | F7: 10 | G7: 3 | H7: 5 | I7: 5 | J7: 9 | K7: 3 | L7: 8
A8: 6 | B8: Data Understanding | C8: The databases present issues of completeness, consistency, or reliability. | D8: 10 | E8: 5 | F8: 10 | G8: 8 | H8: 4 | I8: 8 | J8: 7 | K8: 5 | L8: 6
A9: 7 | B9: Data Understanding | C9: Deadlines for data delivery are frequently not met. | D9: 10 | E9: 5 | F9: 7 | G9: 9 | H9: 4 | I9: 8 | J9: 4 | K9: 6 | L9: 2
A10: 8 | B10: Data Understanding | C10: The data used in the model are not properly documented or understood. | D10: 7 | E10: 8 | F10: 6 | G10: 5 | H10: 3 | I10: 6 | J10: 8 | K10: 4 | L10: 9
A11: 9 | B11: Data Understanding | C11: Teams face difficulties in accessing the necessary data sources. | D11: 10 | E11: 1 | F11: 4 | G11: 9 | H11: 1 | I11: 6 | J11: 9 | K11: 6 | L11: 7
A12: 10 | B12: Data Understanding | C12: There is no continuous monitoring of data quality. | D12: 7 | E12: 5 | F12: 7 | G12: 6 | H12: 6 | I12: 5 | J12: 8 | K12: 2 | L12: 7
A13: 11 | B13: Data Preparation | C13: Data processing is carried out without a well-defined technical standard. | D13: 5 | E13: 6 | F13: 7 | G13: 4 | H13: 6 | I13: 6 | J13: 9 | K13: 3 | L13: 6
A14: 12 | B14: Data Preparation | C14: Feature engineering is performed without clear technical criteria. | D14: 5 | E14: 7 | F14: 6 | G14: 3 | H14: 5 | I14: 6 | J14: 9 | K14: 6 | L14: 7
... A38: 36 | B38: Overview | C38: The maturity of governance regarding the new way of managing the portfolio under the new regulation focused on credit risk. | D38: 10 | E38: 10 | F38: 10 | G38: 8 | H38: 9 | I38: 9 | J38: 7 | K38: 7 | L38: 9

Sheet tabelaas de nota
A1: 1
A2: 2
A3: 3
A4: 4
A5: 5
A6: 6
A7: 7
A8: 8
A9: 9
A10: 10

Sheet Eventos_tabulados
A1: Índice | B1: Nº Etapa | C1: Nº Pergunta | D1: Etapas da Modelagem | E1: Eventos de Risco | F1: Ocorrência | G1: Detecção | H1: Severidade
A2: 1 | B2: 1 | C2: =B2&"."&A2 -> 1.1 | D2: Entendimento do Negócio | E2: Os objetivos da modelagem não são claramente definidos desde o início.
A3: 2 | B3: 1 | C3: =B3&"."&A3 -> 1.2 | D3: Entendimento do Negócio | E3: As exigências regulatórias são mal interpretadas pelas equipes envolvidas.
A4: 3 | B4: 1 | C4: =B4&"."&A4 -> 1.3 | D4: Entendimento do Negócio | E4: Há falhas na comunicação entre as áreas de risco, contabilidade, TI e negócio.
A5: 4 | B5: 1 | C5: =B5&"."&A5 -> 1.4 | D5: Entendimento do Negócio | E5: As responsabilidades no processo de modelagem não estão claramente distribuídas.
A6: 5 | B6: 1 | C6: =B6&"."&A6 -> 1.5 | D6: Entendimento do Negócio | E6: Não existe processo formal para revisar e atualizar o escopo da modelagem.
A7: 6 | B7: 2 | C7: =B7&"."&A2 -> 2.1 | D7: Entendimento dos Dados | E7: As bases de dados apresentam falhas de completude, consistência ou confiabilidade.
A8: 7 | B8: 2 | C8: =B8&"."&A3 -> 2.2 | D8: Entendimento dos Dados | E8: Os prazos para entrega dos dados frequentemente não são cumpridos.
A9: 8 | B9: 2 | C9: =B9&"."&A4 -> 2.3 | D9: Entendimento dos Dados | E9: Os dados utilizados no modelo não estão devidamente documentados ou compreendidos.
A10: 9 | B10: 2 | C10: =B10&"."&A5 -> 2.4 | D10: Entendimento dos Dados | E10: As equipes enfrentam dificuldade para acessar as fontes de dados necessárias.
A11: 10 | B11: 2 | C11: =B11&"."&A6 -> 2.5 | D11: Entendimento dos Dados | E11: Não há monitoramento contínuo da qualidade dos dados.
A12: 11 | B12: 3 | C12: =B12&"."&A2 -> 3.1 | D12: Preparação dos Dados | E12: O tratamento dos dados é realizado sem um padrão técnico bem definido.
A13: 12 | B13: 3 | C13: =B13&"."&A3 -> 3.2 | D13: Preparação dos Dados | E13: A engenharia de variáveis é feita sem critérios técnicos claros.
A14: 13 | B14: 3 | C14: =B14&"."&A4 -> 3.3 | D14: Preparação dos Dados | E14: O processo de preparação dos dados demanda retrabalho frequente.
A15: 14 | B15: 3 | C15: =B15&"."&A5 -> 3.4 | D15: Preparação dos Dados | E15: As transformações de dados não passam por revisão técnica formal.
A16: 15 | B16: 3 | C16: =B16&"."&A6 -> 3.5 | D16: Preparação dos Dados | E16: Não existe repositório centralizado com versões dos datasets utilizados.
A17: 16 | B17: 4 | C17: =B17&"."&A2 -> 4.1 | D17: Modelagem | E17: Os algoritmos escolhidos são inadequados ao problema modelado.
A18: 17 | B18: 4 | C18: =B18&"."&A3 -> 4.2 | D18: Modelagem | E18: A equipe responsável não possui conhecimento técnico suficiente.
A19: 18 | B19: 4 | C19: =B19&"."&A4 -> 4.3 | D19: Modelagem | E19: A introdução de cenários macroeconômicos é feita de forma incorreta ou incompleta.
A20: 19 | B20: 4 | C20: =B20&"."&A5 -> 4.4 | D20: Modelagem | E20: O risco de overfitting não é considerado ou tratado adequadamente.
A21: 20 | B21: 4 | C21: =B21&"."&A6 -> 4.5 | D21: Modelagem | E21: Não são aplicadas técnicas de validação cruzada ou similares.
A22: 21 | B22: 5 | C22: =B22&"."&A2 -> 5.1 | D22: Avaliação do Modelo | E22: Os modelos não são validados com métricas estatísticas adequadas.
A23: 22 | B23: 5 | C23: =B23&"."&A3 -> 5.2 | D23: Avaliação do Modelo | E23: Os testes de estabilidade e aderência regulatória são falhos ou inexistentes.
A24: 23 | B24: 5 | C24: =B24&"."&A4 -> 5.3 | D24: Avaliação do Modelo | E24: Não há comitê ou instância formal de validação técnica dos modelos.
A25: 24 | B25: 5 | C25: =B25&"."&A5 -> 5.4 | D25: Avaliação do Modelo | E25: A validação dos modelos não inclui testes fora da amostra (out-of-sample).
A26: 25 | B26: 5 | C26: =B26&"."&A6 -> 5.5 | D26: Avaliação do Modelo | E26: Os resultados da avaliação não são devidamente documentados e arquivados.
A27: 26 | B27: 6 | C27: =B27&"."&A2 -> 6.1 | D27: Implementação e Monitoramento | E27: A documentação técnica e funcional dos modelos é incompleta ou desatualizada.
A28: 27 | B28: 6 | C28: =B28&"."&A3 -> 6.2 | D28: Implementação e Monitoramento | E28: A integração com os sistemas de TI ou contabilidade é falha ou lenta.
A29: 28 | B29: 6 | C29: =B29&"."&A4 -> 6.3 | D29: Implementação e Monitoramento | E29: Não há cronograma definido para revalidação dos modelos em produção.
A30: 29 | B30: 6 | C30: =B30&"."&A5 -> 6.4 | D30: Implementação e Monitoramento | E30: Os modelos em produção não são acompanhados com indicadores atualizados.
A31: 30 | B31: 6 | C31: =B31&"."&A6 -> 6.5 | D31: Implementação e Monitoramento | E31: Falhas de produção ou erros de cálculo não são rapidamente detectados.
A32: 31 | B32: 7 | C32: =B32&"."&A2 -> 7.1 | D32: Visão Geral | E32: O processo como um todo apresenta falhas recorrentes e falta de controle.
A33: 32 | B33: 7 | C33: =B33&"."&A3 -> 7.2 | D33: Visão Geral | E33: Os controles existentes são insuficientes para mitigar riscos operacionais.
A34: 33 | B34: 7 | C34: =B34&"."&A4 -> 7.3 | D34: Visão Geral | E34: O nível de risco da modelagem da perda esperada é considerado elevado.
A35: 34 | B35: 7 | C35: =B35&"."&A5 -> 7.4 | D35: Visão Geral | E35: A comunicação entre as áreas ao longo do processo é falha ou ineficaz.
A36: 35 | B36: 7 | C36: =B36&"."&A6 -> 7.5 | D36: Visão Geral | E36: A organização não está preparada para adaptar os modelos às mudanças regulatórias.

Sheet Occurence
A1: Scoring | B1: Occurrence | C1: Description
A2: 1 | B2: Extremely Rare | C2: Chance of occurrence lower than 0.1%
A3: 2 | B3: Very Rare | C3: Chance of occurrence lower than 1%
A4: 3 | B4: Rarely Occurs | C4: Chance of occurrence between 1% and 3%
A5: 4 | B5: Has Occurred a Few Times | C5: Chance of occurrence between 3% and 5%
A6: 5 | B6: Occurs Sporadically | C6: Chance of occurrence between 5% and 8%
A7: 6 | B7: Occurs Occasionally | C7: Chance of occurrence between 8% and 15%
A8: 7 | B8: Occurs with Some Regularity | C8: Chance of occurrence between 15% and 25%
A9: 8 | B9: Occurs Frequently | C9: Chance of occurrence between 25% and 35%
A10: 9 | B10: Occurs Very Frequently | C10: Chance of occurrence between 35% and 50%
A11: 10 | B11: Failure Occurs Almost Always | C11: Chance of occurrence greater than 50%

Sheet Detection
A1: Scoring | B1: Detection | C1: Description
A2: 1 | B2: Certain | C2: The failure will be detected immediately during model construction, documentation, or validation (robust and automatic controls are in place).
A3: 2 | B3: Almost Certain | C3: The failure will likely be detected during the statistical validation stage or compliance analysis before implementation.
A4: 3 | B4: High | C4: The failure may be detected if a detailed validation and cross-review among areas (e.g., IT, risk, accounting) is performed.
A5: 4 | B5: Moderately High | C5: The failure may be detected if an in-depth analysis is conducted with access to additional data and explanatory models.
A6: 5 | B6: Moderate | C6: The failure may be detected through formal review plus auxiliary indicators, but it requires the mobilization of specialized resources.
A7: 6 | B7: Low | C7: The failure may be detected only if external teams or internal consultancies are mobilized, which does not occur in the standard process.
A8: 7 | B8: Very Low | C8: The failure is very difficult to detect before production deployment, even with internal review.
A9: 8 | B9: Remote | C9: The failure is extremely difficult to identify and would require specific audits or rare retrospective analyses.
A10: 9 | B10: Very Remote | C10: The failure could only be perceived after causing impact, requiring significant forensic or historical effort.
A11: 10 | B11: Impossible | C11: There are no controls that allow prior detection of the failure; it will only be perceived after loss, non-compliance, or regulatory enforcement.

Sheet Severity
A1: Scoring | B1: Detection | C1: Description
A2: 1 | B2: None | C2: The failure does not affect model performance and has no impact on provisioning calculations or the decision-making process.
A3: 2 | B3: Very Low | C3: The failure may generate statistically irrelevant impact, with no effect on provisioning or decisions, and occurs in very specific scenarios.
A4: 3 | B4: Low | C4: May generate slight distortion in the model outputs, with no relevant impact on accounting or managerial reports.
A5: 4 | B5: Minor | C5: May require additional attention in a specific stage of the process, with limited operational impact and delivery delays.
A6: 5 | B6: Moderate | C6: May impact model stability or lead to inadequate provisioning in certain segments or specific portfolios.
A7: 6 | B7: Moderately High | C7: May lead to revision of credit strategies; failures impact relevant groups and require reclassification or model adjustments.
A8: 7 | B8: High | C8: Significant impact on risk measurement; may distort provisions and require urgent recalibration or reassessment of the model.
A9: 8 | B9: Very High | C9: Generates critical failures in expected loss estimation; may cause regulatory non-compliance or recurring incorrect provisioning.
A10: 9 | B10: Extremely High | C10: Interrupts the use of the model; results become unreliable; severe potential losses; requires intervention and an emergency action plan.
A11: 10 | B11: Catastrophic | C11: Direct impact on compliance with CMN 4966/2021 regulation, compromising the integrity of financial reporting, with risk of sanctions and severe material losses.

Sheet Planilha1
D1: Expert 1 | G1: Expert 2 | J1: Expert 3
A2: Índice | B2: Etapas da Modelagem | C2: Eventos de Risco | D2: Ocorrência | E2: Detecção | F2: Severidade | G2: Ocorrência | H2: Detecção | I2: Severidade | J2: Ocorrência | K2: Detecção | L2: Severidade
A3: 1 | B3: Entendimento do Negócio | C3: Os objetivos da modelagem não são claramente definidos desde o início. | D3: 8 | E3: 7 | F3: 8 | G3: 7 | H3: 7 | I3: 8 | J3: 8 | K3: 4 | L3: 8
A4: 2 | B4: Entendimento do Negócio | C4: As exigências regulatórias são mal interpretadas pelas equipes envolvidas. | D4: 10 | E4: 3 | F4: 7 | G4: 10 | H4: 4 | I4: 9 | J4: 8 | K4: 5 | L4: 6
A5: 3 | B5: Entendimento do Negócio | C5: Há falhas na comunicação entre as áreas de risco, contabilidade, TI e negócio. | D5: 10 | E5: 5 | F5: 8 | G5: 8 | H5: 6 | I5: 5 | J5: 8 | K5: 6 | L5: 4
A6: 4 | B6: Entendimento do Negócio | C6: As responsabilidades no processo de modelagem não estão claramente distribuídas. | D6: 10 | E6: 8 | F6: 10 | G6: 8 | H6: 5 | I6: 8 | J6: 7 | K6: 5 | L6: 9
A7: 5 | B7: Entendimento do Negócio | C7: Não existe processo formal para revisar e atualizar o escopo da modelagem. | D7: 10 | E7: 10 | F7: 10 | G7: 3 | H7: 5 | I7: 5 | J7: 9 | K7: 3 | L7: 8
A8: 6 | B8: Entendimento dos Dados | C8: As bases de dados apresentam falhas de completude, consistência ou confiabilidade. | D8: 10 | E8: 5 | F8: 10 | G8: 8 | H8: 4 | I8: 8 | J8: 7 | K8: 5 | L8: 6
A9: 7 | B9: Entendimento dos Dados | C9: Os prazos para entrega dos dados frequentemente não são cumpridos. | D9: 10 | E9: 5 | F9: 7 | G9: 9 | H9: 4 | I9: 8 | J9: 4 | K9: 6 | L9: 2
A10: 8 | B10: Entendimento dos Dados | C10: Os dados utilizados no modelo não estão devidamente documentados ou compreendidos. | D10: 7 | E10: 8 | F10: 6 | G10: 5 | H10: 3 | I10: 6 | J10: 8 | K10: 4 | L10: 9
A11: 9 | B11: Entendimento dos Dados | C11: As equipes enfrentam dificuldade para acessar as fontes de dados necessárias. | D11: 10 | E11: 1 | F11: 4 | G11: 9 | H11: 1 | I11: 6 | J11: 9 | K11: 6 | L11: 7
A12: 10 | B12: Entendimento dos Dados | C12: Não há monitoramento contínuo da qualidade dos dados. | D12: 7 | E12: 5 | F12: 7 | G12: 6 | H12: 6 | I12: 5 | J12: 8 | K12: 2 | L12: 7
A13: 11 | B13: Preparação dos Dados | C13: O tratamento dos dados é realizado sem um padrão técnico bem definido. | D13: 5 | E13: 6 | F13: 7 | G13: 4 | H13: 6 | I13: 6 | J13: 9 | K13: 3 | L13: 6
A14: 12 | B14: Preparação dos Dados | C14: A engenharia de variáveis é feita sem critérios técnicos claros. | D14: 5 | E14: 7 | F14: 6 | G14: 3 | H14: 5 | I14: 6 | J14: 9 | K14: 6 | L14: 7
... A38: 36 | B38: Visão Geral | C38: A maturidade da governça em relação a nova forma de gerenciar a carteira com a nova regulamentação voltada para risco de crédito. | D38: 10 | E38: 10 | F38: 10 | G38: 8 | H38: 9 | I38: 9 | J38: 7 | K38: 7 | L38: 9

Sheet MASS AND ABNTY
Q2: 36 | R2: 3 | S2: 3 | T2: =S2*R2*Q2 -> 324
D3: K | E3: frame of discernment | H3: Mass Function | K3: Mass Function Normalization | N3: =COUNTIF(N5:N328,"SIM") -> 44
A4: Event | B4: Expert | C4: Type | D4: Scoring | E4: r-1 | F4: r | G4: r+1 | H4: f(r-1) | I4: f® | J4: f(r+1) | K4: f(r-1) | L4: f® | M4: f(r+1) | N4: Excluido
A5: 1 | B5: 1 | C5: O | D5: 8 | E5: =IF(F5-1=0,"",F5-1) -> 7 | F5: =D5 -> 8 | G5: =IF(F5+1=11,"",F5+1) -> 9 | H5: =IF(E5<>"",(1/(0.5*SQRT(2*PI()))) * EXP(-((E5 - $D5)^2)/(2*0.5^2)),"") -> 0.10798193 | I5: =(1/(0.5*SQRT(2*PI()))) * EXP(-((F5 - $D5)^2)/(2*0.5^2)) -> 0.79788456 | J5: =IF(G5<>"",(1/(0.5*SQRT(2*PI()))) * EXP(-((G5 - $D5)^2)/(2*0.5^2)),"") -> 0.10798193 | K5: =IF(H5<>"",H5/(SUM(H5:J5)),"") -> 0.10650698 | L5: =I5/SUM(H5:J5) -> 0.78698604 | M5: =IF(J5<>"",J5/SUM(H5:J5),"") -> 0.10650698
A6: 1 | B6: 2 | C6: O | D6: 7 | E6: =IF(F6-1=0,"",F6-1) -> 6 | F6: =D6 -> 7 | G6: =IF(F6+1=11,"",F6+1) -> 8 | H6: =IF(E6<>"",(1/(0.5*SQRT(2*PI()))) * EXP(-((E6 - $D6)^2)/(2*0.5^2)),"") -> 0.10798193 | I6: =(1/(0.5*SQRT(2*PI()))) * EXP(-((F6 - $D6)^2)/(2*0.5^2)) -> 0.79788456 | J6: =IF(G6<>"",(1/(0.5*SQRT(2*PI()))) * EXP(-((G6 - $D6)^2)/(2*0.5^2)),"") -> 0.10798193 | K6: =IF(H6<>"",H6/(SUM(H6:J6)),"") -> 0.10650698 | L6: =I6/SUM(H6:J6) -> 0.78698604 | M6: =IF(J6<>"",J6/SUM(H6:J6),"") -> 0.10650698
A7: 1 | B7: 3 | C7: O | D7: 8 | E7: =IF(F7-1=0,"",F7-1) -> 7 | F7: =D7 -> 8 | G7: =IF(F7+1=11,"",F7+1) -> 9 | H7: =IF(E7<>"",(1/(0.5*SQRT(2*PI()))) * EXP(-((E7 - $D7)^2)/(2*0.5^2)),"") -> 0.10798193 | I7: =(1/(0.5*SQRT(2*PI()))) * EXP(-((F7 - $D7)^2)/(2*0.5^2)) -> 0.79788456 | J7: =IF(G7<>"",(1/(0.5*SQRT(2*PI()))) * EXP(-((G7 - $D7)^2)/(2*0.5^2)),"") -> 0.10798193 | K7: =IF(H7<>"",H7/(SUM(H7:J7)),"") -> 0.10650698 | L7: =I7/SUM(H7:J7) -> 0.78698604 | M7: =IF(J7<>"",J7/SUM(H7:J7),"") -> 0.10650698
A8: 1 | B8: 1 | C8: D | D8: 7 | E8: =IF(F8-1=0,"",F8-1) -> 6 | F8: =D8 -> 7 | G8: =IF(F8+1=11,"",F8+1) -> 8 | H8: =IF(E8<>"",(1/(0.5*SQRT(2*PI()))) * EXP(-((E8 - $D8)^2)/(2*0.5^2)),"") -> 0.10798193 | I8: =(1/(0.5*SQRT(2*PI()))) * EXP(-((F8 - $D8)^2)/(2*0.5^2)) -> 0.79788456 | J8: =IF(G8<>"",(1/(0.5*SQRT(2*PI()))) * EXP(-((G8 - $D8)^2)/(2*0.5^2)),"") -> 0.10798193 | K8: =IF(H8<>"",H8/(SUM(H8:J8)),"") -> 0.10650698 | L8: =I8/SUM(H8:J8) -> 0.78698604 | M8: =IF(J8<>"",J8/SUM(H8:J8),"") -> 0.10650698
A9: 1 | B9: 2 | C9: D | D9: 7 | E9: =IF(F9-1=0,"",F9-1) -> 6 | F9: =D9 -> 7 | G9: =IF(F9+1=11,"",F9+1) -> 8 | H9: =IF(E9<>"",(1/(0.5*SQRT(2*PI()))) * EXP(-((E9 - $D9)^2)/(2*0.5^2)),"") -> 0.10798193 | I9: =(1/(0.5*SQRT(2*PI()))) * EXP(-((F9 - $D9)^2)/(2*0.5^2)) -> 0.79788456 | J9: =IF(G9<>"",(1/(0.5*SQRT(2*PI()))) * EXP(-((G9 - $D9)^2)/(2*0.5^2)),"") -> 0.10798193 | K9: =IF(H9<>"",H9/(SUM(H9:J9)),"") -> 0.10650698 | L9: =I9/SUM(H9:J9) -> 0.78698604 | M9: =IF(J9<>"",J9/SUM(H9:J9),"") -> 0.10650698
A10: 1 | B10: 3 | C10: D | D10: 4 | E10: =IF(F10-1=0,"",F10-1) -> 3 | F10: =D10 -> 4 | G10: =IF(F10+1=11,"",F10+1) -> 5 | H10: =IF(E10<>"",(1/(0.5*SQRT(2*PI()))) * EXP(-((E10 - $D10)^2)/(2*0.5^2)),"") -> 0.10798193 | I10: =(1/(0.5*SQRT(2*PI()))) * EXP(-((F10 - $D10)^2)/(2*0.5^2)) -> 0.79788456 | J10: =IF(G10<>"",(1/(0.5*SQRT(2*PI()))) * EXP(-((G10 - $D10)^2)/(2*0.5^2)),"") -> 0.10798193 | K10: =IF(H10<>"",H10/(SUM(H10:J10)),"") -> 0.10650698 | L10: =I10/SUM(H10:J10) -> 0.78698604 | M10: =IF(J10<>"",J10/SUM(H10:J10),"") -> 0.10650698 | N10: SIM
A11: 1 | B11: 1 | C11: S | D11: 8 | E11: =IF(F11-1=0,"",F11-1) -> 7 | F11: =D11 -> 8 | G11: =IF(F11+1=11,"",F11+1) -> 9 | H11: =IF(E11<>"",(1/(0.5*SQRT(2*PI()))) * EXP(-((E11 - $D11)^2)/(2*0.5^2)),"") -> 0.10798193 | I11: =(1/(0.5*SQRT(2*PI()))) * EXP(-((F11 - $D11)^2)/(2*0.5^2)) -> 0.79788456 | J11: =IF(G11<>"",(1/(0.5*SQRT(2*PI()))) * EXP(-((G11 - $D11)^2)/(2*0.5^2)),"") -> 0.10798193 | K11: =IF(H11<>"",H11/(SUM(H11:J11)),"") -> 0.10650698 | L11: =I11/SUM(H11:J11) -> 0.78698604 | M11: =IF(J11<>"",J11/SUM(H11:J11),"") -> 0.10650698
A12: 1 | B12: 2 | C12: S | D12: 8 | E12: =IF(F12-1=0,"",F12-1) -> 7 | F12: =D12 -> 8 | G12: =IF(F12+1=11,"",F12+1) -> 9 | H12: =IF(E12<>"",(1/(0.5*SQRT(2*PI()))) * EXP(-((E12 - $D12)^2)/(2*0.5^2)),"") -> 0.10798193 | I12: =(1/(0.5*SQRT(2*PI()))) * EXP(-((F12 - $D12)^2)/(2*0.5^2)) -> 0.79788456 | J12: =IF(G12<>"",(1/(0.5*SQRT(2*PI()))) * EXP(-((G12 - $D12)^2)/(2*0.5^2)),"") -> 0.10798193 | K12: =IF(H12<>"",H12/(SUM(H12:J12)),"") -> 0.10650698 | L12: =I12/SUM(H12:J12) -> 0.78698604 | M12: =IF(J12<>"",J12/SUM(H12:J12),"") -> 0.10650698
A13: 1 | B13: 3 | C13: S | D13: 8 | E13: =IF(F13-1=0,"",F13-1) -> 7 | F13: =D13 -> 8 | G13: =IF(F13+1=11,"",F13+1) -> 9 | H13: =IF(E13<>"",(1/(0.5*SQRT(2*PI()))) * EXP(-((E13 - $D13)^2)/(2*0.5^2)),"") -> 0.10798193 | I13: =(1/(0.5*SQRT(2*PI()))) * EXP(-((F13 - $D13)^2)/(2*0.5^2)) -> 0.79788456 | J13: =IF(G13<>"",(1/(0.5*SQRT(2*PI()))) * EXP(-((G13 - $D13)^2)/(2*0.5^2)),"") -> 0.10798193 | K13: =IF(H13<>"",H13/(SUM(H13:J13)),"") -> 0.10650698 | L13: =I13/SUM(H13:J13) -> 0.78698604 | M13: =IF(J13<>"",J13/SUM(H13:J13),"") -> 0.10650698
A14: 2 | B14: 1 | C14: O | D14: 10 | E14: =IF(F14-1=0,"",F14-1) -> 9 | F14: =D14 -> 10 | G14: =IF(F14+1=11,"",F14+1) | H14: =IF(E14<>"",(1/(0.5*SQRT(2*PI()))) * EXP(-((E14 - $D14)^2)/(2*0.5^2)),"") -> 0.10798193 | I14: =(1/(0.5*SQRT(2*PI()))) * EXP(-((F14 - $D14)^2)/(2*0.5^2)) -> 0.79788456 | J14: =IF(G14<>"",(1/(0.5*SQRT(2*PI()))) * EXP(-((G14 - $D14)^2)/(2*0.5^2)),"") | K14: =IF(H14<>"",H14/(SUM(H14:J14)),"") -> 0.11920292 | L14: =I14/SUM(H14:J14) -> 0.88079708 | M14: =IF(J14<>"",J14/SUM(H14:J14),"")
A15: 2 | B15: 2 | C15: O | D15: 10 | E15: =IF(F15-1=0,"",F15-1) -> 9 | F15: =D15 -> 10 | G15: =IF(F15+1=11,"",F15+1) | H15: =IF(E15<>"",(1/(0.5*SQRT(2*PI()))) * EXP(-((E15 - $D15)^2)/(2*0.5^2)),"") -> 0.10798193 | I15: =(1/(0.5*SQRT(2*PI()))) * EXP(-((F15 - $D15)^2)/(2*0.5^2)) -> 0.79788456 | J15: =IF(G15<>"",(1/(0.5*SQRT(2*PI()))) * EXP(-((G15 - $D15)^2)/(2*0.5^2)),"") | K15: =IF(H15<>"",H15/(SUM(H15:J15)),"") -> 0.11920292 | L15: =I15/SUM(H15:J15) -> 0.88079708 | M15: =IF(J15<>"",J15/SUM(H15:J15),"")
A16: 2 | B16: 3 | C16: O | D16: 8 | E16: =IF(F16-1=0,"",F16-1) -> 7 | F16: =D16 -> 8 | G16: =IF(F16+1=11,"",F16+1) -> 9 | H16: =IF(E16<>"",(1/(0.5*SQRT(2*PI()))) * EXP(-((E16 - $D16)^2)/(2*0.5^2)),"") -> 0.10798193 | I16: =(1/(0.5*SQRT(2*PI()))) * EXP(-((F16 - $D16)^2)/(2*0.5^2)) -> 0.79788456 | J16: =IF(G16<>"",(1/(0.5*SQRT(2*PI()))) * EXP(-((G16 - $D16)^2)/(2*0.5^2)),"") -> 0.10798193 | K16: =IF(H16<>"",H16/(SUM(H16:J16)),"") -> 0.10650698 | L16: =I16/SUM(H16:J16) -> 0.78698604 | M16: =IF(J16<>"",J16/SUM(H16:J16),"") -> 0.10650698
A17: 2 | B17: 1 | C17: D | D17: 3 | E17: =IF(F17-1=0,"",F17-1) -> 2 | F17: =D17 -> 3 | G17: =IF(F17+1=11,"",F17+1) -> 4 | H17: =IF(E17<>"",(1/(0.5*SQRT(2*PI()))) * EXP(-((E17 - $D17)^2)/(2*0.5^2)),"") -> 0.10798193 | I17: =(1/(0.5*SQRT(2*PI()))) * EXP(-((F17 - $D17)^2)/(2*0.5^2)) -> 0.79788456 | J17: =IF(G17<>"",(1/(0.5*SQRT(2*PI()))) * EXP(-((G17 - $D17)^2)/(2*0.5^2)),"") -> 0.10798193 | K17: =IF(H17<>"",H17/(SUM(H17:J17)),"") -> 0.10650698 | L17: =I17/SUM(H17:J17) -> 0.78698604 | M17: =IF(J17<>"",J17/SUM(H17:J17),"") -> 0.10650698
A18: 2 | B18: 2 | C18: D | D18: 4 | E18: =IF(F18-1=0,"",F18-1) -> 3 | F18: =D18 -> 4 | G18: =IF(F18+1=11,"",F18+1) -> 5 | H18: =IF(E18<>"",(1/(0.5*SQRT(2*PI()))) * EXP(-((E18 - $D18)^2)/(2*0.5^2)),"") -> 0.10798193 | I18: =(1/(0.5*SQRT(2*PI()))) * EXP(-((F18 - $D18)^2)/(2*0.5^2)) -> 0.79788456 | J18: =IF(G18<>"",(1/(0.5*SQRT(2*PI()))) * EXP(-((G18 - $D18)^2)/(2*0.5^2)),"") -> 0.10798193 | K18: =IF(H18<>"",H18/(SUM(H18:J18)),"") -> 0.10650698 | L18: =I18/SUM(H18:J18) -> 0.78698604 | M18: =IF(J18<>"",J18/SUM(H18:J18),"") -> 0.10650698
A19: 2 | B19: 3 | C19: D | D19: 5 | E19: =IF(F19-1=0,"",F19-1) -> 4 | F19: =D19 -> 5 | G19: =IF(F19+1=11,"",F19+1) -> 6 | H19: =IF(E19<>"",(1/(0.5*SQRT(2*PI()))) * EXP(-((E19 - $D19)^2)/(2*0.5^2)),"") -> 0.10798193 | I19: =(1/(0.5*SQRT(2*PI()))) * EXP(-((F19 - $D19)^2)/(2*0.5^2)) -> 0.79788456 | J19: =IF(G19<>"",(1/(0.5*SQRT(2*PI()))) * EXP(-((G19 - $D19)^2)/(2*0.5^2)),"") -> 0.10798193 | K19: =IF(H19<>"",H19/(SUM(H19:J19)),"") -> 0.10650698 | L19: =I19/SUM(H19:J19) -> 0.78698604 | M19: =IF(J19<>"",J19/SUM(H19:J19),"") -> 0.10650698
A20: 2 | B20: 1 | C20: S | D20: 7 | E20: =IF(F20-1=0,"",F20-1) -> 6 | F20: =D20 -> 7 | G20: =IF(F20+1=11,"",F20+1) -> 8 | H20: =IF(E20<>"",(1/(0.5*SQRT(2*PI()))) * EXP(-((E20 - $D20)^2)/(2*0.5^2)),"") -> 0.10798193 | I20: =(1/(0.5*SQRT(2*PI()))) * EXP(-((F20 - $D20)^2)/(2*0.5^2)) -> 0.79788456 | J20: =IF(G20<>"",(1/(0.5*SQRT(2*PI()))) * EXP(-((G20 - $D20)^2)/(2*0.5^2)),"") -> 0.10798193 | K20: =IF(H20<>"",H20/(SUM(H20:J20)),"") -> 0.10650698 | L20: =I20/SUM(H20:J20) -> 0.78698604 | M20: =IF(J20<>"",J20/SUM(H20:J20),"") -> 0.10650698
A21: 2 | B21: 2 | C21: S | D21: 9 | E21: =IF(F21-1=0,"",F21-1) -> 8 | F21: =D21 -> 9 | G21: =IF(F21+1=11,"",F21+1) -> 10 | H21: =IF(E21<>"",(1/(0.5*SQRT(2*PI()))) * EXP(-((E21 - $D21)^2)/(2*0.5^2)),"") -> 0.10798193 | I21: =(1/(0.5*SQRT(2*PI()))) * EXP(-((F21 - $D21)^2)/(2*0.5^2)) -> 0.79788456 | J21: =IF(G21<>"",(1/(0.5*SQRT(2*PI()))) * EXP(-((G21 - $D21)^2)/(2*0.5^2)),"") -> 0.10798193 | K21: =IF(H21<>"",H21/(SUM(H21:J21)),"") -> 0.10650698 | L21: =I21/SUM(H21:J21) -> 0.78698604 | M21: =IF(J21<>"",J21/SUM(H21:J21),"") -> 0.10650698
A22: 2 | B22: 3 | C22: S | D22: 6 | E22: =IF(F22-1=0,"",F22-1) -> 5 | F22: =D22 -> 6 | G22: =IF(F22+1=11,"",F22+1) -> 7 | H22: =IF(E22<>"",(1/(0.5*SQRT(2*PI()))) * EXP(-((E22 - $D22)^2)/(2*0.5^2)),"") -> 0.10798193 | I22: =(1/(0.5*SQRT(2*PI()))) * EXP(-((F22 - $D22)^2)/(2*0.5^2)) -> 0.79788456 | J22: =IF(G22<>"",(1/(0.5*SQRT(2*PI()))) * EXP(-((G22 - $D22)^2)/(2*0.5^2)),"") -> 0.10798193 | K22: =IF(H22<>"",H22/(SUM(H22:J22)),"") -> 0.10650698 | L22: =I22/SUM(H22:J22) -> 0.78698604 | M22: =IF(J22<>"",J22/SUM(H22:J22),"") -> 0.10650698
... A28: 3 | B28: 3 | C28: D | D28: 6 | E28: =IF(F28-1=0,"",F28-1) -> 5 | F28: =D28 -> 6 | G28: =IF(F28+1=11,"",F28+1) -> 7 | H28: =IF(E28<>"",(1/(0.5*SQRT(2*PI()))) * EXP(-((E28 - $D28)^2)/(2*0.5^2)),"") -> 0.10798193 | I28: =(1/(0.5*SQRT(2*PI()))) * EXP(-((F28 - $D28)^2)/(2*0.5^2)) -> 0.79788456 | J28: =IF(G28<>"",(1/(0.5*SQRT(2*PI()))) * EXP(-((G28 - $D28)^2)/(2*0.5^2)),"") -> 0.10798193 | K28: =IF(H28<>"",H28/(SUM(H28:J28)),"") -> 0.10650698 | L28: =I28/SUM(H28:J28) -> 0.78698604 | M28: =IF(J28<>"",J28/SUM(H28:J28),"") -> 0.10650698
A29: 3 | B29: 1 | C29: S | D29: 8 | E29: =IF(F29-1=0,"",F29-1) -> 7 | F29: =D29 -> 8 | G29: =IF(F29+1=11,"",F29+1) -> 9 | H29: =IF(E29<>"",(1/(0.5*SQRT(2*PI()))) * EXP(-((E29 - $D29)^2)/(2*0.5^2)),"") -> 0.10798193 | I29: =(1/(0.5*SQRT(2*PI()))) * EXP(-((F29 - $D29)^2)/(2*0.5^2)) -> 0.79788456 | J29: =IF(G29<>"",(1/(0.5*SQRT(2*PI()))) * EXP(-((G29 - $D29)^2)/(2*0.5^2)),"") -> 0.10798193 | K29: =IF(H29<>"",H29/(SUM(H29:J29)),"") -> 0.10650698 | L29: =I29/SUM(H29:J29) -> 0.78698604 | M29: =IF(J29<>"",J29/SUM(H29:J29),"") -> 0.10650698 | N29: SIM
A30: 3 | B30: 2 | C30: S | D30: 5 | E30: =IF(F30-1=0,"",F30-1) -> 4 | F30: =D30 -> 5 | G30: =IF(F30+1=11,"",F30+1) -> 6 | H30: =IF(E30<>"",(1/(0.5*SQRT(2*PI()))) * EXP(-((E30 - $D30)^2)/(2*0.5^2)),"") -> 0.10798193 | I30: =(1/(0.5*SQRT(2*PI()))) * EXP(-((F30 - $D30)^2)/(2*0.5^2)) -> 0.79788456 | J30: =IF(G30<>"",(1/(0.5*SQRT(2*PI()))) * EXP(-((G30 - $D30)^2)/(2*0.5^2)),"") -> 0.10798193 | K30: =IF(H30<>"",H30/(SUM(H30:J30)),"") -> 0.10650698 | L30: =I30/SUM(H30:J30) -> 0.78698604 | M30: =IF(J30<>"",J30/SUM(H30:J30),"") -> 0.10650698
A31: 3 | B31: 3 | C31: S | D31: 4 | E31: =IF(F31-1=0,"",F31-1) -> 3 | F31: =D31 -> 4 | G31: =IF(F31+1=11,"",F31+1) -> 5 | H31: =IF(E31<>"",(1/(0.5*SQRT(2*PI()))) * EXP(-((E31 - $D31)^2)/(2*0.5^2)),"") -> 0.10798193 | I31: =(1/(0.5*SQRT(2*PI()))) * EXP(-((F31 - $D31)^2)/(2*0.5^2)) -> 0.79788456 | J31: =IF(G31<>"",(1/(0.5*SQRT(2*PI()))) * EXP(-((G31 - $D31)^2)/(2*0.5^2)),"") -> 0.10798193 | K31: =IF(H31<>"",H31/(SUM(H31:J31)),"") -> 0.10650698 | L31: =I31/SUM(H31:J31) -> 0.78698604 | M31: =IF(J31<>"",J31/SUM(H31:J31),"") -> 0.10650698
A32: 4 | B32: 1 | C32: O | D32: 10 | E32: =IF(F32-1=0,"",F32-1) -> 9 | F32: =D32 -> 10 | G32: =IF(F32+1=11,"",F32+1) | H32: =IF(E32<>"",(1/(0.5*SQRT(2*PI()))) * EXP(-((E32 - $D32)^2)/(2*0.5^2)),"") -> 0.10798193 | I32: =(1/(0.5*SQRT(2*PI()))) * EXP(-((F32 - $D32)^2)/(2*0.5^2)) -> 0.79788456 | J32: =IF(G32<>"",(1/(0.5*SQRT(2*PI()))) * EXP(-((G32 - $D32)^2)/(2*0.5^2)),"") | K32: =IF(H32<>"",H32/(SUM(H32:J32)),"") -> 0.11920292 | L32: =I32/SUM(H32:J32) -> 0.88079708 | M32: =IF(J32<>"",J32/SUM(H32:J32),"")
A33: 4 | B33: 2 | C33: O | D33: 8 | E33: =IF(F33-1=0,"",F33-1) -> 7 | F33: =D33 -> 8 | G33: =IF(F33+1=11,"",F33+1) -> 9 | H33: =IF(E33<>"",(1/(0.5*SQRT(2*PI()))) * EXP(-((E33 - $D33)^2)/(2*0.5^2)),"") -> 0.10798193 | I33: =(1/(0.5*SQRT(2*PI()))) * EXP(-((F33 - $D33)^2)/(2*0.5^2)) -> 0.79788456 | J33: =IF(G33<>"",(1/(0.5*SQRT(2*PI()))) * EXP(-((G33 - $D33)^2)/(2*0.5^2)),"") -> 0.10798193 | K33: =IF(H33<>"",H33/(SUM(H33:J33)),"") -> 0.10650698 | L33: =I33/SUM(H33:J33) -> 0.78698604 | M33: =IF(J33<>"",J33/SUM(H33:J33),"") -> 0.10650698
A34: 4 | B34: 3 | C34: O | D34: 7 | E34: =IF(F34-1=0,"",F34-1) -> 6 | F34: =D34 -> 7 | G34: =IF(F34+1=11,"",F34+1) -> 8 | H34: =IF(E34<>"",(1/(0.5*SQRT(2*PI()))) * EXP(-((E34 - $D34)^2)/(2*0.5^2)),"") -> 0.10798193 | I34: =(1/(0.5*SQRT(2*PI()))) * EXP(-((F34 - $D34)^2)/(2*0.5^2)) -> 0.79788456 | J34: =IF(G34<>"",(1/(0.5*SQRT(2*PI()))) * EXP(-((G34 - $D34)^2)/(2*0.5^2)),"") -> 0.10798193 | K34: =IF(H34<>"",H34/(SUM(H34:J34)),"") -> 0.10650698 | L34: =I34/SUM(H34:J34) -> 0.78698604 | M34: =IF(J34<>"",J34/SUM(H34:J34),"") -> 0.10650698
A35: 4 | B35: 1 | C35: D | D35: 8 | E35: =IF(F35-1=0,"",F35-1) -> 7 | F35: =D35 -> 8 | G35: =IF(F35+1=11,"",F35+1) -> 9 | H35: =IF(E35<>"",(1/(0.5*SQRT(2*PI()))) * EXP(-((E35 - $D35)^2)/(2*0.5^2)),"") -> 0.10798193 | I35: =(1/(0.5*SQRT(2*PI()))) * EXP(-((F35 - $D35)^2)/(2*0.5^2)) -> 0.79788456 | J35: =IF(G35<>"",(1/(0.5*SQRT(2*PI()))) * EXP(-((G35 - $D35)^2)/(2*0.5^2)),"") -> 0.10798193 | K35: =IF(H35<>"",H35/(SUM(H35:J35)),"") -> 0.10650698 | L35: =I35/SUM(H35:J35) -> 0.78698604 | M35: =IF(J35<>"",J35/SUM(H35:J35),"") -> 0.10650698 | N35: SIM
A36: 4 | B36: 2 | C36: D | D36: 5 | E36: =IF(F36-1=0,"",F36-1) -> 4 | F36: =D36 -> 5 | G36: =IF(F36+1=11,"",F36+1) -> 6 | H36: =IF(E36<>"",(1/(0.5*SQRT(2*PI()))) * EXP(-((E36 - $D36)^2)/(2*0.5^2)),"") -> 0.10798193 | I36: =(1/(0.5*SQRT(2*PI()))) * EXP(-((F36 - $D36)^2)/(2*0.5^2)) -> 0.79788456 | J36: =IF(G36<>"",(1/(0.5*SQRT(2*PI()))) * EXP(-((G36 - $D36)^2)/(2*0.5^2)),"") -> 0.10798193 | K36: =IF(H36<>"",H36/(SUM(H36:J36)),"") -> 0.10650698 | L36: =I36/SUM(H36:J36) -> 0.78698604 | M36: =IF(J36<>"",J36/SUM(H36:J36),"") -> 0.10650698
A37: 4 | B37: 3 | C37: D | D37: 5 | E37: =IF(F37-1=0,"",F37-1) -> 4 | F37: =D37 -> 5 | G37: =IF(F37+1=11,"",F37+1) -> 6 | H37: =IF(E37<>"",(1/(0.5*SQRT(2*PI()))) * EXP(-((E37 - $D37)^2)/(2*0.5^2)),"") -> 0.10798193 | I37: =(1/(0.5*SQRT(2*PI()))) * EXP(-((F37 - $D37)^2)/(2*0.5^2)) -> 0.79788456 | J37: =IF(G37<>"",(1/(0.5*SQRT(2*PI()))) * EXP(-((G37 - $D37)^2)/(2*0.5^2)),"") -> 0.10798193 | K37: =IF(H37<>"",H37/(SUM(H37:J37)),"") -> 0.10650698 | L37: =I37/SUM(H37:J37) -> 0.78698604 | M37: =IF(J37<>"",J37/SUM(H37:J37),"") -> 0.10650698
A38: 4 | B38: 1 | C38: S | D38: 10 | E38: =IF(F38-1=0,"",F38-1) -> 9 | F38: =D38 -> 10 | G38: =IF(F38+1=11,"",F38+1) | H38: =IF(E38<>"",(1/(0.5*SQRT(2*PI()))) * EXP(-((E38 - $D38)^2)/(2*0.5^2)),"") -> 0.10798193 | I38: =(1/(0.5*SQRT(2*PI()))) * EXP(-((F38 - $D38)^2)/(2*0.5^2)) -> 0.79788456 | J38: =IF(G38<>"",(1/(0.5*SQRT(2*PI()))) * EXP(-((G38 - $D38)^2)/(2*0.5^2)),"") | K38: =IF(H38<>"",H38/(SUM(H38:J38)),"") -> 0.11920292 | L38: =I38/SUM(H38:J38) -> 0.88079708 | M38: =IF(J38<>"",J38/SUM(H38:J38),"")
A39: 4 | B39: 2 | C39: S | D39: 8 | E39: =IF(F39-1=0,"",F39-1) -> 7 | F39: =D39 -> 8 | G39: =IF(F39+1=11,"",F39+1) -> 9 | H39: =IF(E39<>"",(1/(0.5*SQRT(2*PI()))) * EXP(-((E39 - $D39)^2)/(2*0.5^2)),"") -> 0.10798193 | I39: =(1/(0.5*SQRT(2*PI()))) * EXP(-((F39 - $D39)^2)/(2*0.5^2)) -> 0.79788456 | J39: =IF(G39<>"",(1/(0.5*SQRT(2*PI()))) * EXP(-((G39 - $D39)^2)/(2*0.5^2)),"") -> 0.10798193 | K39: =IF(H39<>"",H39/(SUM(H39:J39)),"") -> 0.10650698 | L39: =I39/SUM(H39:J39) -> 0.78698604 | M39: =IF(J39<>"",J39/SUM(H39:J39),"") -> 0.10650698
A40: 4 | B40: 3 | C40: S | D40: 9 | E40: =IF(F40-1=0,"",F40-1) -> 8 | F40: =D40 -> 9 | G40: =IF(F40+1=11,"",F40+1) -> 10 | H40: =IF(E40<>"",(1/(0.5*SQRT(2*PI()))) * EXP(-((E40 - $D40)^2)/(2*0.5^2)),"") -> 0.10798193 | I40: =(1/(0.5*SQRT(2*PI()))) * EXP(-((F40 - $D40)^2)/(2*0.5^2)) -> 0.79788456 | J40: =IF(G40<>"",(1/(0.5*SQRT(2*PI()))) * EXP(-((G40 - $D40)^2)/(2*0.5^2)),"") -> 0.10798193 | K40: =IF(H40<>"",H40/(SUM(H40:J40)),"") -> 0.10650698 | L40: =I40/SUM(H40:J40) -> 0.78698604 | M40: =IF(J40<>"",J40/SUM(H40:J40),"") -> 0.10650698
A41: 5 | B41: 1 | C41: O | D41: 10 | E41: =IF(F41-1=0,"",F41-1) -> 9 | F41: =D41 -> 10 | G41: =IF(F41+1=11,"",F41+1) | H41: =IF(E41<>"",(1/(0.5*SQRT(2*PI()))) * EXP(-((E41 - $D41)^2)/(2*0.5^2)),"") -> 0.10798193 | I41: =(1/(0.5*SQRT(2*PI()))) * EXP(-((F41 - $D41)^2)/(2*0.5^2)) -> 0.79788456 | J41: =IF(G41<>"",(1/(0.5*SQRT(2*PI()))) * EXP(-((G41 - $D41)^2)/(2*0.5^2)),"") | K41: =IF(H41<>"",H41/(SUM(H41:J41)),"") -> 0.11920292 | L41: =I41/SUM(H41:J41) -> 0.88079708 | M41: =IF(J41<>"",J41/SUM(H41:J41),"")
A42: 5 | B42: 2 | C42: O | D42: 3 | E42: =IF(F42-1=0,"",F42-1) -> 2 | F42: =D42 -> 3 | G42: =IF(F42+1=11,"",F42+1) -> 4 | H42: =IF(E42<>"",(1/(0.5*SQRT(2*PI()))) * EXP(-((E42 - $D42)^2)/(2*0.5^2)),"") -> 0.10798193 | I42: =(1/(0.5*SQRT(2*PI()))) * EXP(-((F42 - $D42)^2)/(2*0.5^2)) -> 0.79788456 | J42: =IF(G42<>"",(1/(0.5*SQRT(2*PI()))) * EXP(-((G42 - $D42)^2)/(2*0.5^2)),"") -> 0.10798193 | K42: =IF(H42<>"",H42/(SUM(H42:J42)),"") -> 0.10650698 | L42: =I42/SUM(H42:J42) -> 0.78698604 | M42: =IF(J42<>"",J42/SUM(H42:J42),"") -> 0.10650698 | N42: SIM
A43: 5 | B43: 3 | C43: O | D43: 9 | E43: =IF(F43-1=0,"",F43-1) -> 8 | F43: =D43 -> 9 | G43: =IF(F43+1=11,"",F43+1) -> 10 | H43: =IF(E43<>"",(1/(0.5*SQRT(2*PI()))) * EXP(-((E43 - $D43)^2)/(2*0.5^2)),"") -> 0.10798193 | I43: =(1/(0.5*SQRT(2*PI()))) * EXP(-((F43 - $D43)^2)/(2*0.5^2)) -> 0.79788456 | J43: =IF(G43<>"",(1/(0.5*SQRT(2*PI()))) * EXP(-((G43 - $D43)^2)/(2*0.5^2)),"") -> 0.10798193 | K43: =IF(H43<>"",H43/(SUM(H43:J43)),"") -> 0.10650698 | L43: =I43/SUM(H43:J43) -> 0.78698604 | M43: =IF(J43<>"",J43/SUM(H43:J43),"") -> 0.10650698
A44: 5 | B44: 1 | C44: D | D44: 10 | E44: =IF(F44-1=0,"",F44-1) -> 9 | F44: =D44 -> 10 | G44: =IF(F44+1=11,"",F44+1) | H44: =IF(E44<>"",(1/(0.5*SQRT(2*PI()))) * EXP(-((E44 - $D44)^2)/(2*0.5^2)),"") -> 0.10798193 | I44: =(1/(0.5*SQRT(2*PI()))) * EXP(-((F44 - $D44)^2)/(2*0.5^2)) -> 0.79788456 | J44: =IF(G44<>"",(1/(0.5*SQRT(2*PI()))) * EXP(-((G44 - $D44)^2)/(2*0.5^2)),"") | K44: =IF(H44<>"",H44/(SUM(H44:J44)),"") -> 0.11920292 | L44: =I44/SUM(H44:J44) -> 0.88079708 | M44: =IF(J44<>"",J44/SUM(H44:J44),"") | N44: SIM
A45: 5 | B45: 2 | C45: D | D45: 5 | E45: =IF(F45-1=0,"",F45-1) -> 4 | F45: =D45 -> 5 | G45: =IF(F45+1=11,"",F45+1) -> 6 | H45: =IF(E45<>"",(1/(0.5*SQRT(2*PI()))) * EXP(-((E45 - $D45)^2)/(2*0.5^2)),"") -> 0.10798193 | I45: =(1/(0.5*SQRT(2*PI()))) * EXP(-((F45 - $D45)^2)/(2*0.5^2)) -> 0.79788456 | J45: =IF(G45<>"",(1/(0.5*SQRT(2*PI()))) * EXP(-((G45 - $D45)^2)/(2*0.5^2)),"") -> 0.10798193 | K45: =IF(H45<>"",H45/(SUM(H45:J45)),"") -> 0.10650698 | L45: =I45/SUM(H45:J45) -> 0.78698604 | M45: =IF(J45<>"",J45/SUM(H45:J45),"") -> 0.10650698
A46: 5 | B46: 3 | C46: D | D46: 3 | E46: =IF(F46-1=0,"",F46-1) -> 2 | F46: =D46 -> 3 | G46: =IF(F46+1=11,"",F46+1) -> 4 | H46: =IF(E46<>"",(1/(0.5*SQRT(2*PI()))) * EXP(-((E46 - $D46)^2)/(2*0.5^2)),"") -> 0.10798193 | I46: =(1/(0.5*SQRT(2*PI()))) * EXP(-((F46 - $D46)^2)/(2*0.5^2)) -> 0.79788456 | J46: =IF(G46<>"",(1/(0.5*SQRT(2*PI()))) * EXP(-((G46 - $D46)^2)/(2*0.5^2)),"") -> 0.10798193 | K46: =IF(H46<>"",H46/(SUM(H46:J46)),"") -> 0.10650698 | L46: =I46/SUM(H46:J46) -> 0.78698604 | M46: =IF(J46<>"",J46/SUM(H46:J46),"") -> 0.10650698
...

Sheet RPN_POND_MASS
A1: Event | B1: Type | C1: RPN
A2: 1 | B2: D | C2: 7
A3: 1 | B3: O | C3: 7.6667
A4: 1 | B4: S | C4: 8
A5: 2 | B5: D | C5: 4
A6: 2 | B6: O | C6: 9.2539
A7: 2 | B7: S | C7: 7.3333
A8: 3 | B8: D | C8: 5.6667
A9: 3 | B9: O | C9: 8.6269
A10: 3 | B10: S | C10: 4.5
A11: 4 | B11: D | C11: 5
A12: 4 | B12: O | C12: 8.2936
A13: 4 | B13: S | C13: 8.9603
... A108: 36 | B108: S | C108: 9.2936

Sheet Validação
A1: k | B1: f(r-1) | C1: f(r) | D1: f(r+1)
A2: 6 | B2: x
A3: 7 | C3: x
A4: 8 | D4: x
A7: k | B7: Esp Q | C7: Soma Ma | D7: Media
A8: 6 | B8: 1 e 2 | C8: =Planilha3!K8+Planilha3!K9 -> 0.21301396 | D8: =C8/3 -> 0.071004653 | E8: =A8*D8 -> 0.42602792
A9: 7 | B9: 1 e 2 | C9: =Planilha3!L8+Planilha3!L9 -> 1.5739721 | D9: =C9/2 -> 0.78698604 | E9: =A9*D9 -> 5.5089023
A10: 8 | B10: 1 e 2 | C10: =Planilha3!M8+Planilha3!M9 -> 0.21301396 | D10: =C10/2 -> 0.10650698 | E10: =A10*D10 -> 0.85205583
E12: =SUM(E8:E10) -> 6.786986
A15: k | B15: f(r-1) | C15: f(r) | D15: f(r+1)
A16: 3 | B16: x
A17: 4 | B17: x | C17: x
A18: 5 | C18: x | D18: x
A19: 6 | D19: x
A21: 3s
A22: k | B22: Esp Q | C22: Soma Ma | D22: Media
A23: 3 | B23: 3 (r-1) | C23: 0.10650698 | D23: 0.053253489 | E23: 0.15976047
A24: 4 | B24: 2(r-1) e 3r | C24: 0.89349302 | D24: 0.44674651 | E24: 1.786986
A25: 5 | B25: 2r e 3 (r+1) | C25: 0.89349302 | D25: 0.44674651 | E25: 2.2337326
A26: 6 | B26: 2 (r+1) | C26: 0.10650698 | D26: 0.053253489 | E26: 0.31952094
D28: =SUM(D23:D26) -> 1 | E28: 4.5
A30: 4s
A31: k | B31: Esp Q | C31: Soma Ma | D31: Media
A32: 7 | B32: 2 (r-1) | C32: 0.10650698 | D32: 0.035502326 | E32: 0.24851628
A33: 8 | B33: 2(r) e 3r-1 | C33: 0.89349302 | D33: 0.29783101 | E33: 2.3826481
A34: 9 | B34: 1r-1 e 2 (r+1) e 3r | C34: 1.0126959 | D34: 0.33756531 | E34: 3.0380878
A35: 10 | B35: 1r e 3 (r+1) | C35: 0.98730406 | D35: 0.32910135 | E35: 3.2910135
E37: 8.9602657

Sheet FINAL_RESULTS
A1: Event | B1: Modelling Stage | C1: K_O | D1: RPN_O | E1: K_D | F1: RPN_D | G1: K_S | H1: RPN_S | I1: RPNf | J1: Ranking
A2: 36 | B2: =VLOOKUP(A2,Questions!$A:$B,2,0) -> Overview | C2: 0.0601 | D2: 8.2936 | E2: 0.0663 | F2: 8.6269 | G2: 0.3391 | H2: 9.2936 | I2: 664.93903 | J2: 1
A3: 33 | B3: =VLOOKUP(A3,Questions!$A:$B,2,0) -> Overview | C3: 0.79 | D3: 9.8808 | E3: 0.0597 | F3: 6.3333 | G3: 0.2718 | H3: 9.2539 | I3: 579.09121 | J3: 2
A4: 30 | B4: =VLOOKUP(A4,Questions!$A:$B,2,0) -> Implementation and Monitoring | C4: 0.008 | D4: 7.9603 | E4: 0.642 | F4: 7 | G4: 0.3258 | H4: 8.6667 | I4: 482.92672 | J4: 3
A5: 1 | B5: =VLOOKUP(A5,Questions!$A:$B,2,0) -> Business Understanding | C5: 0.3258 | D5: 7.6667 | E5: 0.642 | F5: 7 | G5: 0.642 | H5: 8 | I5: 429.3352 | J5: 4
A6: 34 | B6: =VLOOKUP(A6,Questions!$A:$B,2,0) -> Overview | C6: 0.0601 | D6: 8.2936 | E6: 0.2216 | F6: 6.3333 | G6: 0.0597 | H6: 7.3333 | I6: 385.18787 | J6: 5
A7: 21 | B7: =VLOOKUP(A7,Questions!$A:$B,2,0) -> Model Evaluation | C7: 0.0076 | D7: 5 | E7: 0.1876 | F7: 9.4404 | G7: 0.1155 | H7: 8 | I7: 377.616 | J7: 6
A8: 4 | B8: =VLOOKUP(A8,Questions!$A:$B,2,0) -> Business Understanding | C8: 0.0601 | D8: 8.2936 | E8: 0.642 | F8: 5 | G8: 0.1227 | H8: 8.9603 | I8: 371.56572 | J8: 7
A9: 7 | B9: =VLOOKUP(A9,Questions!$A:$B,2,0) -> Data Understanding | C9: 0.1876 | D9: 9.4404 | E9: 0.1155 | F9: 5 | G9: 0.1676 | H9: 7.5 | I9: 354.015 | J9: 8
A10: 5 | B10: =VLOOKUP(A10,Questions!$A:$B,2,0) -> Business Understanding | C10: 0.1876 | D10: 9.4404 | E10: 0.0113 | F10: 4 | G10: 0.0127 | H10: 8.9404 | I10: 337.60381 | J10: 9
A11: 6 | B11: =VLOOKUP(A11,Questions!$A:$B,2,0) -> Data Understanding | C11: 0.0601 | D11: 8.2936 | E11: 0.3258 | F11: 4.6667 | G11: 0.008 | H11: 7.9603 | I11: 308.09341 | J11: 10
A12: 35 | B12: =VLOOKUP(A12,Questions!$A:$B,2,0) -> Overview | C12: 0.642 | D12: 5 | E12: 0.0113 | F12: 7 | G12: 0.3258 | H12: 8.3333 | I12: 291.6655 | J12: 11
A13: 32 | B13: =VLOOKUP(A13,Questions!$A:$B,2,0) -> Overview | C13: 0.1676 | D13: 6.5 | E13: 0.0597 | F13: 5.6667 | G13: 0.1676 | H13: 7.5 | I13: 276.25162 | J13: 12
... A36: 23 | B36: =VLOOKUP(A36,Questions!$A:$B,2,0) -> Model Evaluation | C36: 0.642 | D36: 3 | E36: 0.79 | F36: 1.1192 | G36: 0.1227 | H36: 8.9603 | I36: 30.085103 | J36: 35
A37: 22 | B37: =VLOOKUP(A37,Questions!$A:$B,2,0) -> Model Evaluation | C37: 0.0601 | D37: 8.2936 | G37: 0.3258 | H37: 7.6667 | J37: 36

Sheet Planilha3
A4: Event | B4: Expert | C4: Type | D4: Score | E4: r-1 | F4: r | G4: r+1 | H4: f(r-1) | I4: f® | J4: f(r+1) | K4: f(r-1) | L4: f(r) | M4: f(r+1) | O4: k | P4: f(r-1) | Q4: f(r) | R4: f(r+1)
A5: 1 | B5: 1 | C5: O | D5: 8 | E5: 7 | F5: 8 | G5: 9 | H5: 0.10798193 | I5: 0.79788456 | J5: 0.10798193 | K5: 0.10650698 | L5: 0.78698604 | M5: 0.10650698
A6: 1 | B6: 2 | C6: O | D6: 7 | E6: 6 | F6: 7 | G6: 8 | H6: 0.10798193 | I6: 0.79788456 | J6: 0.10798193 | K6: 0.10650698 | L6: 0.78698604 | M6: 0.10650698
A7: 1 | B7: 3 | C7: O | D7: 8 | E7: 7 | F7: 8 | G7: 9 | H7: 0.10798193 | I7: 0.79788456 | J7: 0.10798193 | K7: 0.10650698 | L7: 0.78698604 | M7: 0.10650698
A8: 1 | B8: 1 | C8: D | D8: 7 | E8: 6 | F8: 7 | G8: 8 | H8: 0.10798193 | I8: 0.79788456 | J8: 0.10798193 | K8: 0.10650698 | L8: 0.78698604 | M8: 0.10650698
A9: 1 | B9: 2 | C9: D | D9: 7 | E9: 6 | F9: 7 | G9: 8 | H9: 0.10798193 | I9: 0.79788456 | J9: 0.10798193 | K9: 0.10650698 | L9: 0.78698604 | M9: 0.10650698
A10: 1 | B10: 1 | C10: S | D10: 8 | E10: 7 | F10: 8 | G10: 9 | H10: 0.10798193 | I10: 0.79788456 | J10: 0.10798193 | K10: 0.10650698 | L10: 0.78698604 | M10: 0.10650698
A11: 1 | B11: 2 | C11: S | D11: 8 | E11: 7 | F11: 8 | G11: 9 | H11: 0.10798193 | I11: 0.79788456 | J11: 0.10798193 | K11: 0.10650698 | L11: 0.78698604 | M11: 0.10650698
A12: 1 | B12: 3 | C12: S | D12: 8 | E12: 7 | F12: 8 | G12: 9 | H12: 0.10798193 | I12: 0.79788456 | J12: 0.10798193 | K12: 0.10650698 | L12: 0.78698604 | M12: 0.10650698
A13: 2 | B13: 1 | C13: O | D13: 10 | E13: 9 | F13: 10 | H13: 0.10798193 | I13: 0.79788456 | K13: 0.11920292 | L13: 0.88079708
A14: 2 | B14: 2 | C14: O | D14: 10 | E14: 9 | F14: 10 | H14: 0.10798193 | I14: 0.79788456 | K14: 0.11920292 | L14: 0.88079708
A15: 2 | B15: 3 | C15: O | D15: 8 | E15: 7 | F15: 8 | G15: 9 | H15: 0.10798193 | I15: 0.79788456 | J15: 0.10798193 | K15: 0.10650698 | L15: 0.78698604 | M15: 0.10650698
A16: 2 | B16: 1 | C16: D | D16: 3 | E16: 2 | F16: 3 | G16: 4 | H16: 0.10798193 | I16: 0.79788456 | J16: 0.10798193 | K16: 0.10650698 | L16: 0.78698604 | M16: 0.10650698
A17: 2 | B17: 2 | C17: D | D17: 4 | E17: 3 | F17: 4 | G17: 5 | H17: 0.10798193 | I17: 0.79788456 | J17: 0.10798193 | K17: 0.10650698 | L17: 0.78698604 | M17: 0.10650698
A18: 2 | B18: 3 | C18: D | D18: 5 | E18: 4 | F18: 5 | G18: 6 | H18: 0.10798193 | I18: 0.79788456 | J18: 0.10798193 | K18: 0.10650698 | L18: 0.78698604 | M18: 0.10650698
A19: 2 | B19: 1 | C19: S | D19: 7 | E19: 6 | F19: 7 | G19: 8 | H19: 0.10798193 | I19: 0.79788456 | J19: 0.10798193 | K19: 0.10650698 | L19: 0.78698604 | M19: 0.10650698
A20: 2 | B20: 2 | C20: S | D20: 9 | E20: 8 | F20: 9 | G20: 10 | H20: 0.10798193 | I20: 0.79788456 | J20: 0.10798193 | K20: 0.10650698 | L20: 0.78698604 | M20: 0.10650698
A21: 2 | B21: 3 | C21: S | D21: 6 | E21: 5 | F21: 6 | G21: 7 | H21: 0.10798193 | I21: 0.79788456 | J21: 0.10798193 | K21: 0.10650698 | L21: 0.78698604 | M21: 0.10650698
A22: 3 | B22: 1 | C22: O | D22: 10 | E22: 9 | F22: 10 | H22: 0.10798193 | I22: 0.79788456 | K22: 0.11920292 | L22: 0.88079708
A23: 3 | B23: 2 | C23: O | D23: 8 | E23: 7 | F23: 8 | G23: 9 | H23: 0.10798193 | I23: 0.79788456 | J23: 0.10798193 | K23: 0.10650698 | L23: 0.78698604 | M23: 0.10650698
A24: 3 | B24: 3 | C24: O | D24: 8 | E24: 7 | F24: 8 | G24: 9 | H24: 0.10798193 | I24: 0.79788456 | J24: 0.10798193 | K24: 0.10650698 | L24: 0.78698604 | M24: 0.10650698
A25: 3 | B25: 1 | C25: D | D25: 5 | E25: 4 | F25: 5 | G25: 6 | H25: 0.10798193 | I25: 0.79788456 | J25: 0.10798193 | K25: 0.10650698 | L25: 0.78698604 | M25: 0.10650698
A26: 3 | B26: 2 | C26: D | D26: 6 | E26: 5 | F26: 6 | G26: 7 | H26: 0.10798193 | I26: 0.79788456 | J26: 0.10798193 | K26: 0.10650698 | L26: 0.78698604 | M26: 0.10650698
A27: 3 | B27: 3 | C27: D | D27: 6 | E27: 5 | F27: 6 | G27: 7 | H27: 0.10798193 | I27: 0.79788456 | J27: 0.10798193 | K27: 0.10650698 | L27: 0.78698604 | M27: 0.10650698
A28: 3 | B28: 2 | C28: S | D28: 5 | E28: 4 | F28: 5 | G28: 6 | H28: 0.10798193 | I28: 0.79788456 | J28: 0.10798193 | K28: 0.10650698 | L28: 0.78698604 | M28: 0.10650698 | O28: 3 | P28: x
A29: 3 | B29: 3 | C29: S | D29: 4 | E29: 3 | F29: 4 | G29: 5 | H29: 0.10798193 | I29: 0.79788456 | J29: 0.10798193 | K29: 0.10650698 | L29: 0.78698604 | M29: 0.10650698 | O29: 4 | P29: x | Q29: x
A30: 4 | B30: 1 | C30: O | D30: 10 | E30: 9 | F30: 10 | H30: 0.10798193 | I30: 0.79788456 | K30: 0.11920292 | L30: 0.88079708
A31: 4 | B31: 2 | C31: O | D31: 8 | E31: 7 | F31: 8 | G31: 9 | H31: 0.10798193 | I31: 0.79788456 | J31: 0.10798193 | K31: 0.10650698 | L31: 0.78698604 | M31: 0.10650698
A32: 4 | B32: 3 | C32: O | D32: 7 | E32: 6 | F32: 7 | G32: 8 | H32: 0.10798193 | I32: 0.79788456 | J32: 0.10798193 | K32: 0.10650698 | L32: 0.78698604 | M32: 0.10650698
A33: 4 | B33: 2 | C33: D | D33: 5 | E33: 4 | F33: 5 | G33: 6 | H33: 0.10798193 | I33: 0.79788456 | J33: 0.10798193 | K33: 0.10650698 | L33: 0.78698604 | M33: 0.10650698
A34: 4 | B34: 3 | C34: D | D34: 5 | E34: 4 | F34: 5 | G34: 6 | H34: 0.10798193 | I34: 0.79788456 | J34: 0.10798193 | K34: 0.10650698 | L34: 0.78698604 | M34: 0.10650698
A35: 4 | B35: 1 | C35: S | D35: 10 | E35: 9 | F35: 10 | H35: 0.10798193 | I35: 0.79788456 | K35: 0.11920292 | L35: 0.88079708
A36: 4 | B36: 2 | C36: S | D36: 8 | E36: 7 | F36: 8 | G36: 9 | H36: 0.10798193 | I36: 0.79788456 | J36: 0.10798193 | K36: 0.10650698 | L36: 0.78698604 | M36: 0.10650698
A37: 4 | B37: 3 | C37: S | D37: 9 | E37: 8 | F37: 9 | G37: 10 | H37: 0.10798193 | I37: 0.79788456 | J37: 0.10798193 | K37: 0.10650698 | L37: 0.78698604 | M37: 0.10650698
A38: 5 | B38: 1 | C38: O | D38: 10 | E38: 9 | F38: 10 | H38: 0.10798193 | I38: 0.79788456 | K38: 0.11920292 | L38: 0.88079708
A39: 5 | B39: 3 | C39: O | D39: 9 | E39: 8 | F39: 9 | G39: 10 | H39: 0.10798193 | I39: 0.79788456 | J39: 0.10798193 | K39: 0.10650698 | L39: 0.78698604 | M39: 0.10650698
A40: 5 | B40: 2 | C40: D | D40: 5 | E40: 4 | F40: 5 | G40: 6 | H40: 0.10798193 | I40: 0.79788456 | J40: 0.10798193 | K40: 0.10650698 | L40: 0.78698604 | M40: 0.10650698
A41: 5 | B41: 3 | C41: D | D41: 3 | E41: 2 | F41: 3 | G41: 4 | H41: 0.10798193 | I41: 0.79788456 | J41: 0.10798193 | K41: 0.10650698 | L41: 0.78698604 | M41: 0.10650698
A42: 5 | B42: 1 | C42: S | D42: 10 | E42: 9 | F42: 10 | H42: 0.10798193 | I42: 0.79788456 | K42: 0.11920292 | L42: 0.88079708
A43: 5 | B43: 3 | C43: S | D43: 8 | E43: 7 | F43: 8 | G43: 9 | H43: 0.10798193 | I43: 0.79788456 | J43: 0.10798193 | K43: 0.10650698 | L43: 0.78698604 | M43: 0.10650698
...

Sheet Eventos (2)
B1: Ocorrência | C1: Detecção | D1: Severidade
A2: 1. Entendimento do Negócio
A4: 1.1 Os objetivos da modelagem não são claramente definidos desde o início.
A5: 1.2 As exigências regulatórias são mal interpretadas pelas equipes envolvidas.
A6: 1.3 Há falhas na comunicação entre as áreas de risco, contabilidade, TI e negócio.
A7: 1.4 As responsabilidades no processo de modelagem não estão claramente distribuídas.
A8: 1.5 Não existe processo formal para revisar e atualizar o escopo da modelagem.
A10: 2. Entendimento dos Dados
A12: 2.1 As bases de dados apresentam falhas de completude, consistência ou confiabilidade.
A13: 2.2 Os prazos para entrega dos dados frequentemente não são cumpridos.
A14: 2.3 Os dados utilizados no modelo não estão devidamente documentados ou compreendidos.
A15: 2.4 As equipes enfrentam dificuldade para acessar as fontes de dados necessárias.
A16: 2.5 Não há monitoramento contínuo da qualidade dos dados.
... A57: 7.5 A organização não está preparada para adaptar os modelos às mudanças regulatórias.
